<?xml version="1.0" encoding="utf-8"?>
<!-- This URDF was automatically created by SolidWorks to URDF Exporter! Originally created by Stephen Brawner (brawner@gmail.com) 
     Commit Version: 1.6.0-1-g15f4949  Build Version: 1.6.7594.29634
     For more information, please see http://wiki.ros.org/sw_urdf_exporter -->
<robot
  name="rcm">
  <link
    name="base_link">
    <inertial>
      <origin
        xyz="-1.7214E-06 -0.00015696 0.053136"
        rpy="0 0 0" />
      <mass
        value="0.54888" />
      <inertia
        ixx="0.00051158"
        ixy="1.3334E-09"
        ixz="-1.4584E-09"
        iyy="0.00064416"
        iyz="-1.873E-09"
        izz="0.00063919" />
    </inertial>
    <visual>
      <origin
        xyz="0 0 0"
        rpy="0 0 0" />
      <geometry>
        <mesh
          filename="package://rcm/meshes/base_link.STL" />
      </geometry>
      <material
        name="">
        <color
          rgba="0.79216 0.81961 0.93333 1" />
      </material>
    </visual>
    <collision>
      <origin
        xyz="0 0 0"
        rpy="0 0 0" />
      <geometry>
        <mesh
          filename="package://rcm/meshes/base_link.STL" />
      </geometry>
    </collision>
  </link>
  <link
    name="Link1">
    <inertial>
      <origin
        xyz="-1.0426E-06 0.017456 0.033231"
        rpy="0 0 0" />
      <mass
        value="0.34082" />
      <inertia
        ixx="0.00024163"
        ixy="-1.1458E-12"
        ixz="-4.6996E-14"
        iyy="0.00025274"
        iyz="2.9218E-06"
        izz="0.00025121" />
    </inertial>
    <visual>
      <origin
        xyz="0 0 0"
        rpy="0 0 0" />
      <geometry>
        <mesh
          filename="package://rcm/meshes/Link1.STL" />
      </geometry>
      <material
        name="">
        <color
          rgba="0.79216 0.81961 0.93333 1" />
      </material>
    </visual>
    <collision>
      <origin
        xyz="0 0 0"
        rpy="0 0 0" />
      <geometry>
        <mesh
          filename="package://rcm/meshes/Link1.STL" />
      </geometry>
    </collision>
  </link>
  <joint
    name="Link1_joint"
    type="revolute">
    <origin
      xyz="0 0 0.098695"
      rpy="0 0 0" />
    <parent
      link="base_link" />
    <child
      link="Link1" />
    <axis
      xyz="0 0 1" />
    <limit
      lower="-10"
      upper="10"
      effort="10"
      velocity="10" />
  </joint>
  <link
    name="Link2_1">
    <inertial>
      <origin
        xyz="0.055013 -5.3701E-12 0.00034718"
        rpy="0 0 0" />
      <mass
        value="0.044237" />
      <inertia
        ixx="4.5719E-06"
        ixy="-1.4076E-10"
        ixz="2.5464E-10"
        iyy="4.1666E-05"
        iyz="-1.2118E-14"
        izz="3.8711E-05" />
    </inertial>
    <visual>
      <origin
        xyz="0 0 0"
        rpy="0 0 0" />
      <geometry>
        <mesh
          filename="package://rcm/meshes/Link2_1.STL" />
      </geometry>
      <material
        name="">
        <color
          rgba="0.79216 0.81961 0.93333 1" />
      </material>
    </visual>
    <collision>
      <origin
        xyz="0 0 0"
        rpy="0 0 0" />
      <geometry>
        <mesh
          filename="package://rcm/meshes/Link2_1.STL" />
      </geometry>
    </collision>
  </link>
  <joint
    name="Link2_1_joint"
    type="revolute">
    <origin
      xyz="0 0 0.055554"
      rpy="-1.5708 0 0" />
    <parent
      link="Link1" />
    <child
      link="Link2_1" />
    <axis
      xyz="0 0 1" />
    <limit
      lower="-10"
      upper="10"
      effort="10"
      velocity="10" />
    <mimic
      joint="Link2_1_joint"
      multiplier="1"
      offset="0" />
  </joint>
  <link
    name="Link3_1">
    <inertial>
      <origin
        xyz="0.078951 -1.1102E-16 1.1102E-16"
        rpy="0 0 0" />
      <mass
        value="0.043996" />
      <inertia
        ixx="1.4695E-05"
        ixy="1.4229E-19"
        ixz="-9.7168E-21"
        iyy="0.00010124"
        iyz="1.2196E-20"
        izz="8.7267E-05" />
    </inertial>
    <visual>
      <origin
        xyz="0 0 0"
        rpy="0 0 0" />
      <geometry>
        <mesh
          filename="package://rcm/meshes/Link3_1.STL" />
      </geometry>
      <material
        name="">
        <color
          rgba="0.79216 0.81961 0.93333 1" />
      </material>
    </visual>
    <collision>
      <origin
        xyz="0 0 0"
        rpy="0 0 0" />
      <geometry>
        <mesh
          filename="package://rcm/meshes/Link3_1.STL" />
      </geometry>
    </collision>
  </link>
  <joint
    name="Link3_1_joint"
    type="revolute">
    <origin
      xyz="0.072 0 0"
      rpy="0 0 -1.5708" />
    <parent
      link="Link2_1" />
    <child
      link="Link3_1" />
    <axis
      xyz="0 0 1" />
    <limit
      lower="-10"
      upper="10"
      effort="10"
      velocity="10" />
  </joint>
  <link
    name="Link_ee">
    <inertial>
      <origin
        xyz="-0.0019955 -0.022493 0.00050357"
        rpy="0 0 0" />
      <mass
        value="0.092307" />
      <inertia
        ixx="1.7415E-05"
        ixy="-1.8139E-07"
        ixz="3.0732E-11"
        iyy="9.6059E-05"
        iyz="-5.5841E-12"
        izz="9.4065E-05" />
    </inertial>
    <visual>
      <origin
        xyz="0 0 0"
        rpy="0 0 0" />
      <geometry>
        <mesh
          filename="package://rcm/meshes/Link_ee.STL" />
      </geometry>
      <material
        name="">
        <color
          rgba="0.84314 0.81569 0.75294 1" />
      </material>
    </visual>
    <collision>
      <origin
        xyz="0 0 0"
        rpy="0 0 0" />
      <geometry>
        <mesh
          filename="package://rcm/meshes/Link_ee.STL" />
      </geometry>
    </collision>
  </link>
  <joint
    name="Link_ee_joint"
    type="revolute">
    <origin
      xyz="0.1675 0.04 0"
      rpy="0 0 -1.5708" />
    <parent
      link="Link3_1" />
    <child
      link="Link_ee" />
    <axis
      xyz="0 0 1" />
    <limit
      lower="-10"
      upper="10"
      effort="10"
      velocity="10" />
  </joint>
  <link
    name="Link_E">
    <inertial>
      <origin
        xyz="0.028599 0.00046138 0.00729"
        rpy="0 0 0" />
      <mass
        value="0.023256" />
      <inertia
        ixx="2.0848E-06"
        ixy="7.5146E-09"
        ixz="-6.1806E-09"
        iyy="2.7906E-06"
        iyz="1.1288E-08"
        izz="1.8708E-06" />
    </inertial>
    <visual>
      <origin
        xyz="0 0 0"
        rpy="0 0 0" />
      <geometry>
        <mesh
          filename="package://rcm/meshes/Link_E.STL" />
      </geometry>
      <material
        name="">
        <color
          rgba="0.89412 0.79216 0.73333 1" />
      </material>
    </visual>
    <collision>
      <origin
        xyz="0 0 0"
        rpy="0 0 0" />
      <geometry>
        <mesh
          filename="package://rcm/meshes/Link_E.STL" />
      </geometry>
    </collision>
  </link>
  <joint
    name="Link_E_joint"
    type="prismatic">
    <origin
      xyz="0.032512 -0.037 0"
      rpy="1.5708 0 1.5381" />
    <parent
      link="Link_ee" />
    <child
      link="Link_E" />
    <axis
      xyz="0 0 1" />
    <limit
      lower="-0.03"
      upper="0.04"
      effort="10"
      velocity="10" />
  </joint>
  <link
    name="Link3_2">
    <inertial>
      <origin
        xyz="0.078951 -2.2204E-16 0"
        rpy="0 0 0" />
      <mass
        value="0.043996" />
      <inertia
        ixx="1.4695E-05"
        ixy="1.7597E-19"
        ixz="-7.3583E-21"
        iyy="0.00010124"
        iyz="-2.2739E-22"
        izz="8.7267E-05" />
    </inertial>
    <visual>
      <origin
        xyz="0 0 0"
        rpy="0 0 0" />
      <geometry>
        <mesh
          filename="package://rcm/meshes/Link3_2.STL" />
      </geometry>
      <material
        name="">
        <color
          rgba="0.79216 0.81961 0.93333 1" />
      </material>
    </visual>
    <collision>
      <origin
        xyz="0 0 0"
        rpy="0 0 0" />
      <geometry>
        <mesh
          filename="package://rcm/meshes/Link3_2.STL" />
      </geometry>
    </collision>
  </link>
  <joint
    name="Link3_2_joint"
    type="revolute">
    <origin
      xyz="0.112 0 0"
      rpy="0 0 -1.5708" />
    <parent
      link="Link2_1" />
    <child
      link="Link3_2" />
    <axis
      xyz="0 0 1" />
    <limit
      lower="-10"
      upper="10"
      effort="10"
      velocity="10" />
    <mimic
      joint="Link3_1_joint"
      multiplier="1"
      offset="0" />
  </joint>
  <link
    name="Link2_2">
    <inertial>
      <origin
        xyz="0.061889 8.3267E-17 -0.0001"
        rpy="0 0 0" />
      <mass
        value="0.039322" />
      <inertia
        ixx="4.29E-06"
        ixy="8.939E-24"
        ixz="1.022E-18"
        iyy="4.6463E-05"
        iyz="2.6082E-22"
        izz="4.3641E-05" />
    </inertial>
    <visual>
      <origin
        xyz="0 0 0"
        rpy="0 0 0" />
      <geometry>
        <mesh
          filename="package://rcm/meshes/Link2_2.STL" />
      </geometry>
      <material
        name="">
        <color
          rgba="0.79216 0.81961 0.93333 1" />
      </material>
    </visual>
    <collision>
      <origin
        xyz="0 0 0"
        rpy="0 0 0" />
      <geometry>
        <mesh
          filename="package://rcm/meshes/Link2_2.STL" />
      </geometry>
    </collision>
  </link>
  <joint
    name="Link2_2_joint"
    type="revolute">
    <origin
      xyz="0 0 0.095554"
      rpy="-1.5708 0 0" />
    <parent
      link="Link1" />
    <child
      link="Link2_2" />
    <axis
      xyz="0 0 1" />
    <limit
      lower="-10"
      upper="10"
      effort="10"
      velocity="10" />
    <mimic
      joint="Link2_1_joint"
      multiplier="1"
      offset="0" />
  </joint>
</robot>