<sdf version='1.6'>
  <model name='rcm'>
    <link name='base_link'>
      <pose frame=''>0 0 0 0 -0 0</pose>
      <inertial>
        <pose frame=''>-2e-06 -0.000157 0.053136 0 -0 0</pose>
        <mass>0.54888</mass>
        <inertia>
          <ixx>0.00051158</ixx>
          <ixy>1.3334e-09</ixy>
          <ixz>-1.4584e-09</ixz>
          <iyy>0.00064416</iyy>
          <iyz>-1.873e-09</iyz>
          <izz>0.00063919</izz>
        </inertia>
      </inertial>
      <collision name='base_link_collision'>
        <pose frame=''>0 0 0 0 -0 0</pose>
        <geometry>
          <mesh>
            <scale>1 1 1</scale>
            <uri>model://rcm/meshes/base_link.STL</uri>
          </mesh>
        </geometry>
      </collision>
      <visual name='base_link_visual'>
        <pose frame=''>0 0 0 0 -0 0</pose>
        <geometry>
          <mesh>
            <scale>1 1 1</scale>
            <uri>model://rcm/meshes/base_link.STL</uri>
          </mesh>
        </geometry>
      </visual>
    </link>
    <link name='Link1'>
      <pose frame=''>0 0 0.098695 0 -0 0</pose>
      <inertial>
        <pose frame=''>-1e-06 0.017456 0.033231 0 -0 0</pose>
        <mass>0.34082</mass>
        <inertia>
          <ixx>0.00024163</ixx>
          <ixy>-1.1458e-12</ixy>
          <ixz>-4.6996e-14</ixz>
          <iyy>0.00025274</iyy>
          <iyz>2.9218e-06</iyz>
          <izz>0.00025121</izz>
        </inertia>
      </inertial>
      <collision name='Link1_collision'>
        <pose frame=''>0 0 0 0 -0 0</pose>
        <geometry>
          <mesh>
            <scale>1 1 1</scale>
            <uri>model://rcm/meshes/Link1.STL</uri>
          </mesh>
        </geometry>
      </collision>
      <visual name='Link1_visual'>
        <pose frame=''>0 0 0 0 -0 0</pose>
        <geometry>
          <mesh>
            <scale>1 1 1</scale>
            <uri>model://rcm/meshes/Link1.STL</uri>
          </mesh>
        </geometry>
      </visual>
    </link>
    <joint name='Link1_joint' type='revolute'>
      <child>Link1</child>
      <parent>base_link</parent>
      <axis>
        <xyz>0 0 1</xyz>
        <limit>
          <lower>-10</lower>
          <upper>10</upper>
          <effort>10</effort>
          <velocity>10</velocity>
        </limit>
        <dynamics>
          <spring_reference>0</spring_reference>
          <spring_stiffness>0</spring_stiffness>
        </dynamics>
        <use_parent_model_frame>1</use_parent_model_frame>
      </axis>
    </joint>
    <link name='Link2_1'>
      <pose frame=''>0 0 0.154249 -1.5708 0 0</pose>
      <inertial>
        <pose frame=''>0.055013 -0 0.000347 0 -0 0</pose>
        <mass>0.044237</mass>
        <inertia>
          <ixx>4.5719e-06</ixx>
          <ixy>-1.4076e-10</ixy>
          <ixz>2.5464e-10</ixz>
          <iyy>4.1666e-05</iyy>
          <iyz>-1.2118e-14</iyz>
          <izz>3.8711e-05</izz>
        </inertia>
      </inertial>
      <collision name='Link2_1_collision'>
        <pose frame=''>0 0 0 0 -0 0</pose>
        <geometry>
          <mesh>
            <scale>1 1 1</scale>
            <uri>model://rcm/meshes/Link2_1.STL</uri>
          </mesh>
        </geometry>
      </collision>
      <visual name='Link2_1_visual'>
        <pose frame=''>0 0 0 0 -0 0</pose>
        <geometry>
          <mesh>
            <scale>1 1 1</scale>
            <uri>model://rcm/meshes/Link2_1.STL</uri>
          </mesh>
        </geometry>
      </visual>
    </link>
    <joint name='Link2_1_joint' type='revolute'>
      <child>Link2_1</child>
      <parent>Link1</parent>
      <axis>
        <xyz>0 1 -4e-06</xyz>
        <limit>
          <lower>-10</lower>
          <upper>10</upper>
          <effort>10</effort>
          <velocity>10</velocity>
        </limit>
        <dynamics>
          <spring_reference>0</spring_reference>
          <spring_stiffness>0</spring_stiffness>
        </dynamics>
        <use_parent_model_frame>1</use_parent_model_frame>
      </axis>
    </joint>
    <link name='Link3_1'>
      <pose frame=''>0.072 0 0.154249 2.35619 -1.57079 2.35619</pose>
      <inertial>
        <pose frame=''>0.078951 -0 0 0 -0 0</pose>
        <mass>0.043996</mass>
        <inertia>
          <ixx>1.4695e-05</ixx>
          <ixy>1.4229e-19</ixy>
          <ixz>-9.7168e-21</ixz>
          <iyy>0.00010124</iyy>
          <iyz>1.2196e-20</iyz>
          <izz>8.7267e-05</izz>
        </inertia>
      </inertial>
      <collision name='Link3_1_collision'>
        <pose frame=''>0 0 0 0 -0 0</pose>
        <geometry>
          <mesh>
            <scale>1 1 1</scale>
            <uri>model://rcm/meshes/Link3_1.STL</uri>
          </mesh>
        </geometry>
      </collision>
      <visual name='Link3_1_visual'>
        <pose frame=''>0 0 0 0 -0 0</pose>
        <geometry>
          <mesh>
            <scale>1 1 1</scale>
            <uri>model://rcm/meshes/Link3_1.STL</uri>
          </mesh>
        </geometry>
      </visual>
    </link>
    <joint name='Link3_1_joint' type='revolute'>
      <child>Link3_1</child>
      <parent>Link2_1</parent>
      <axis>
        <xyz>-0 1 -4e-06</xyz>
        <limit>
          <lower>-10</lower>
          <upper>10</upper>
          <effort>10</effort>
          <velocity>10</velocity>
        </limit>
        <dynamics>
          <spring_reference>0</spring_reference>
          <spring_stiffness>0</spring_stiffness>
        </dynamics>
        <use_parent_model_frame>1</use_parent_model_frame>
      </axis>
    </joint>
    <link name='Link_ee'>
      <pose frame=''>0.111999 1e-06 0.321749 1.5708 7e-06 -3.14159</pose>
      <inertial>
        <pose frame=''>-0.001995 -0.022493 0.000504 0 -0 0</pose>
        <mass>0.092307</mass>
        <inertia>
          <ixx>1.7415e-05</ixx>
          <ixy>-1.8139e-07</ixy>
          <ixz>3.0732e-11</ixz>
          <iyy>9.6059e-05</iyy>
          <iyz>-5.5841e-12</iyz>
          <izz>9.4065e-05</izz>
        </inertia>
      </inertial>
      <collision name='Link_ee_collision'>
        <pose frame=''>0 0 0 0 -0 0</pose>
        <geometry>
          <mesh>
            <scale>1 1 1</scale>
            <uri>model://rcm/meshes/Link_ee.STL</uri>
          </mesh>
        </geometry>
      </collision>
      <visual name='Link_ee_visual'>
        <pose frame=''>0 0 0 0 -0 0</pose>
        <geometry>
          <mesh>
            <scale>1 1 1</scale>
            <uri>model://rcm/meshes/Link_ee.STL</uri>
          </mesh>
        </geometry>
      </visual>
    </link>
    <joint name='Link_ee_joint' type='revolute'>
      <child>Link_ee</child>
      <parent>Link3_1</parent>
      <axis>
        <xyz>-0 1 -4e-06</xyz>
        <limit>
          <lower>-10</lower>
          <upper>10</upper>
          <effort>10</effort>
          <velocity>10</velocity>
        </limit>
        <dynamics>
          <spring_reference>0</spring_reference>
          <spring_stiffness>0</spring_stiffness>
        </dynamics>
        <use_parent_model_frame>1</use_parent_model_frame>
      </axis>
    </joint>
    <link name='Link_E'>
      <pose frame=''>0.079488 0 0.284749 -3.14148 -1.53809 3.14148</pose>
      <inertial>
        <pose frame=''>0.028599 0.000461 0.00729 0 -0 0</pose>
        <mass>0.023256</mass>
        <inertia>
          <ixx>2.0848e-06</ixx>
          <ixy>7.5146e-09</ixy>
          <ixz>-6.1806e-09</ixz>
          <iyy>2.7906e-06</iyy>
          <iyz>1.1288e-08</iyz>
          <izz>1.8708e-06</izz>
        </inertia>
      </inertial>
      <collision name='Link_E_collision'>
        <pose frame=''>0 0 0 0 -0 0</pose>
        <geometry>
          <mesh>
            <scale>1 1 1</scale>
            <uri>model://rcm/meshes/Link_E.STL</uri>
          </mesh>
        </geometry>
      </collision>
      <visual name='Link_E_visual'>
        <pose frame=''>0 0 0 0 -0 0</pose>
        <geometry>
          <mesh>
            <scale>1 1 1</scale>
            <uri>model://rcm/meshes/Link_E.STL</uri>
          </mesh>
        </geometry>
      </visual>
    </link>
    <joint name='Link_E_joint' type='prismatic'>
      <child>Link_E</child>
      <parent>Link_ee</parent>
      <axis>
        <xyz>-0.999465 -4e-06 -0.032698</xyz>
        <limit>
          <lower>-0.03</lower>
          <upper>0.04</upper>
          <effort>10</effort>
          <velocity>10</velocity>
        </limit>
        <dynamics>
          <spring_reference>0</spring_reference>
          <spring_stiffness>0</spring_stiffness>
        </dynamics>
        <use_parent_model_frame>1</use_parent_model_frame>
      </axis>
    </joint>
    <link name='Link3_2'>
      <pose frame=''>0.112 0 0.154249 2.35619 -1.57079 2.35619</pose>
      <inertial>
        <pose frame=''>0.078951 -0 0 0 -0 0</pose>
        <mass>0.043996</mass>
        <inertia>
          <ixx>1.4695e-05</ixx>
          <ixy>1.7597e-19</ixy>
          <ixz>-7.3583e-21</ixz>
          <iyy>0.00010124</iyy>
          <iyz>-2.2739e-22</iyz>
          <izz>8.7267e-05</izz>
        </inertia>
      </inertial>
      <collision name='Link3_2_collision'>
        <pose frame=''>0 0 0 0 -0 0</pose>
        <geometry>
          <mesh>
            <scale>1 1 1</scale>
            <uri>model://rcm/meshes/Link3_2.STL</uri>
          </mesh>
        </geometry>
      </collision>
      <visual name='Link3_2_visual'>
        <pose frame=''>0 0 0 0 -0 0</pose>
        <geometry>
          <mesh>
            <scale>1 1 1</scale>
            <uri>model://rcm/meshes/Link3_2.STL</uri>
          </mesh>
        </geometry>
      </visual>
    </link>
    <joint name='Link3_2_joint' type='revolute'>
      <child>Link3_2</child>
      <parent>Link2_1</parent>
      <axis>
        <xyz>-0 1 -4e-06</xyz>
        <limit>
          <lower>-10</lower>
          <upper>10</upper>
          <effort>10</effort>
          <velocity>10</velocity>
        </limit>
        <dynamics>
          <spring_reference>0</spring_reference>
          <spring_stiffness>0</spring_stiffness>
        </dynamics>
        <use_parent_model_frame>1</use_parent_model_frame>
      </axis>
    </joint>
    <link name='Link2_2'>
      <pose frame=''>0 0 0.194249 -1.5708 0 0</pose>
      <inertial>
        <pose frame=''>0.061889 0 -0.0001 0 -0 0</pose>
        <mass>0.039322</mass>
        <inertia>
          <ixx>4.29e-06</ixx>
          <ixy>8.939e-24</ixy>
          <ixz>1.022e-18</ixz>
          <iyy>4.6463e-05</iyy>
          <iyz>2.6082e-22</iyz>
          <izz>4.3641e-05</izz>
        </inertia>
      </inertial>
      <collision name='Link2_2_collision'>
        <pose frame=''>0 0 0 0 -0 0</pose>
        <geometry>
          <mesh>
            <scale>1 1 1</scale>
            <uri>model://rcm/meshes/Link2_2.STL</uri>
          </mesh>
        </geometry>
      </collision>
      <visual name='Link2_2_visual'>
        <pose frame=''>0 0 0 0 -0 0</pose>
        <geometry>
          <mesh>
            <scale>1 1 1</scale>
            <uri>model://rcm/meshes/Link2_2.STL</uri>
          </mesh>
        </geometry>
      </visual>
    </link>
    <joint name='Link2_2_joint' type='revolute'>
      <child>Link2_2</child>
      <parent>Link1</parent>
      <axis>
        <xyz>0 1 -4e-06</xyz>
        <limit>
          <lower>-10</lower>
          <upper>10</upper>
          <effort>10</effort>
          <velocity>10</velocity>
        </limit>
        <dynamics>
          <spring_reference>0</spring_reference>
          <spring_stiffness>0</spring_stiffness>
        </dynamics>
        <use_parent_model_frame>1</use_parent_model_frame>
      </axis>
    </joint>
  </model>
</sdf>
