<?xml version="1.0" encoding="utf-8"?>
<!-- This URDF was automatically created by SolidWorks to URDF Exporter! Originally created by Stephen Brawner (brawner@gmail.com) 
     Commit Version: 1.6.0-1-g15f4949  Build Version: 1.6.7594.29634
     For more information, please see http://wiki.ros.org/sw_urdf_exporter -->
<robot
  name="rcm">
  <link
    name="base_link">
    <inertial>
      <origin
        xyz="0.1095 0.10854 0.21101"
        rpy="0 0 0" />
      <mass
        value="0.54888" />
      <inertia
        ixx="0.00064416"
        ixy="-1.873E-09"
        ixz="1.3334E-09"
        iyy="0.00063919"
        iyz="-1.4584E-09"
        izz="0.00051158" />
    </inertial>
    <visual>
      <origin
        xyz="0 0 0"
        rpy="0 0 0" />
      <geometry>
        <mesh
          filename="package://rcm/meshes/base_link.STL" />
      </geometry>
      <material
        name="">
        <color
          rgba="0.79216 0.81961 0.93333 1" />
      </material>
    </visual>
    <collision>
      <origin
        xyz="0 0 0"
        rpy="0 0 0" />
      <geometry>
        <mesh
          filename="package://rcm/meshes/base_link.STL" />
      </geometry>
    </collision>
  </link>
  <link
    name="Link1">
    <inertial>
      <origin
        xyz="0.016647 0.037777 0.0058834"
        rpy="0 0 0" />
      <mass
        value="0.34082" />
      <inertia
        ixx="0.0002515"
        ixy="2.7548E-06"
        ixz="3.4909E-06"
        iyy="0.00025121"
        iyz="9.7361E-07"
        izz="0.00024286" />
    </inertial>
    <visual>
      <origin
        xyz="0 0 0"
        rpy="0 0 0" />
      <geometry>
        <mesh
          filename="package://rcm/meshes/Link1.STL" />
      </geometry>
      <material
        name="">
        <color
          rgba="0.79216 0.81961 0.93333 1" />
      </material>
    </visual>
    <collision>
      <origin
        xyz="0 0 0"
        rpy="0 0 0" />
      <geometry>
        <mesh
          filename="package://rcm/meshes/Link1.STL" />
      </geometry>
    </collision>
  </link>
  <joint
    name="Link1_joint"
    type="revolute">
    <origin
      xyz="0.10907 -0.21102 0.14956"
      rpy="1.5708 0 0" />
    <parent
      link="base_link" />
    <child
      link="Link1" />
    <axis
      xyz="0 0 0" />
    <limit
      lower="-1.57"
      upper="1.57"
      effort="1000"
      velocity="0.2" />
  </joint>
  <link
    name="Link2_1">
    <inertial>
      <origin
        xyz="0.00044718 0.0075 -0.0019869"
        rpy="0 0 0" />
      <mass
        value="0.044237" />
      <inertia
        ixx="3.8711E-05"
        ixy="1.2118E-14"
        ixz="2.5464E-10"
        iyy="4.1666E-05"
        iyz="1.4076E-10"
        izz="4.5719E-06" />
    </inertial>
    <visual>
      <origin
        xyz="0 0 0"
        rpy="0 0 0" />
      <geometry>
        <mesh
          filename="package://rcm/meshes/Link2_1.STL" />
      </geometry>
      <material
        name="">
        <color
          rgba="0.79216 0.81961 0.93333 1" />
      </material>
    </visual>
    <collision>
      <origin
        xyz="0 0 0"
        rpy="0 0 0" />
      <geometry>
        <mesh
          filename="package://rcm/meshes/Link2_1.STL" />
      </geometry>
    </collision>
  </link>
  <joint
    name="Link2_1_joint"
    type="revolute">
    <origin
      xyz="-0.0189 0.0526 0.053776"
      rpy="0 -0.33972 0" />
    <parent
      link="Link1" />
    <child
      link="Link2_1" />
    <axis
      xyz="0 0 0" />
    <limit
      lower="-1.57"
      upper="1.57"
      effort="1000"
      velocity="0.2" />
    <mimic
      joint="Link2_1_joint"
      multiplier="1"
      offset="0" />
  </joint>
  <link
    name="Link3_1">
    <inertial>
      <origin
        xyz="0 0.005 0.016549"
        rpy="0 0 0" />
      <mass
        value="0.043996" />
      <inertia
        ixx="8.7267E-05"
        ixy="6.7763E-21"
        ixz="4.3902E-20"
        iyy="0.00010124"
        iyz="-5.9436E-20"
        izz="1.4695E-05" />
    </inertial>
    <visual>
      <origin
        xyz="0 0 0"
        rpy="0 0 0" />
      <geometry>
        <mesh
          filename="package://rcm/meshes/Link3_1.STL" />
      </geometry>
      <material
        name="">
        <color
          rgba="0.79216 0.81961 0.93333 1" />
      </material>
    </visual>
    <collision>
      <origin
        xyz="0 0 0"
        rpy="0 0 0" />
      <geometry>
        <mesh
          filename="package://rcm/meshes/Link3_1.STL" />
      </geometry>
    </collision>
  </link>
  <joint
    name="Link3_1_joint"
    type="revolute">
    <origin
      xyz="0.0001 0.103 0.01"
      rpy="1.5708 0 0" />
    <parent
      link="Link2_1" />
    <child
      link="Link3_1" />
    <axis
      xyz="0 0 0" />
    <limit
      lower="-1.57"
      upper="1.57"
      effort="1000"
      velocity="0.2" />
  </joint>
  <link
    name="Link_ee">
    <inertial>
      <origin
        xyz="3.4616E-06 -0.018493 0.026995"
        rpy="0 0 0" />
      <mass
        value="0.092307" />
      <inertia
        ixx="9.4065E-05"
        ixy="-6.6218E-13"
        ixz="-2.0226E-10"
        iyy="9.6059E-05"
        iyz="1.8139E-07"
        izz="1.7415E-05" />
    </inertial>
    <visual>
      <origin
        xyz="0 0 0"
        rpy="0 0 0" />
      <geometry>
        <mesh
          filename="package://rcm/meshes/Link_ee.STL" />
      </geometry>
      <material
        name="">
        <color
          rgba="0.84314 0.81569 0.75294 1" />
      </material>
    </visual>
    <collision>
      <origin
        xyz="0 0 0"
        rpy="0 0 0" />
      <geometry>
        <mesh
          filename="package://rcm/meshes/Link_ee.STL" />
      </geometry>
    </collision>
  </link>
  <joint
    name="Link_ee_joint"
    type="revolute">
    <origin
      xyz="0.0005 0.02 -0.068"
      rpy="-1.5708 0 0" />
    <parent
      link="Link3_1" />
    <child
      link="Link_ee" />
    <axis
      xyz="0 0 0" />
    <limit
      lower="-1.57"
      upper="1.57"
      effort="1000"
      velocity="0.2" />
  </joint>
  <link
    name="Link_E">
    <inertial>
      <origin
        xyz="-0.0057317 0.048346 3.8622E-05"
        rpy="0 0 0" />
      <mass
        value="0.023256" />
      <inertia
        ixx="1.8707E-06"
        ixy="-8.174E-10"
        ixz="1.1527E-08"
        iyy="2.085E-06"
        iyz="-7.1419E-09"
        izz="2.7906E-06" />
    </inertial>
    <visual>
      <origin
        xyz="0 0 0"
        rpy="0 0 0" />
      <geometry>
        <mesh
          filename="package://rcm/meshes/Link_E.STL" />
      </geometry>
      <material
        name="">
        <color
          rgba="0.89412 0.79216 0.73333 1" />
      </material>
    </visual>
    <collision>
      <origin
        xyz="0 0 0"
        rpy="0 0 0" />
      <geometry>
        <mesh
          filename="package://rcm/meshes/Link_E.STL" />
      </geometry>
    </collision>
  </link>
  <joint
    name="Link_E_joint"
    type="prismatic">
    <origin
      xyz="0 -0.053 -0.01"
      rpy="3.1416 -1.5708 0" />
    <parent
      link="Link_ee" />
    <child
      link="Link_E" />
    <axis
      xyz="0 0 0" />
    <limit
      lower="0"
      upper="0.08"
      effort="1000"
      velocity="0.2" />
  </joint>
  <link
    name="Link3_2">
    <inertial>
      <origin
        xyz="0 0.005 0.016549"
        rpy="0 0 0" />
      <mass
        value="0.043996" />
      <inertia
        ixx="8.7267E-05"
        ixy="1.1858E-20"
        ixz="4.5015E-20"
        iyy="0.00010124"
        iyz="-2.1834E-19"
        izz="1.4695E-05" />
    </inertial>
    <visual>
      <origin
        xyz="0 0 0"
        rpy="0 0 0" />
      <geometry>
        <mesh
          filename="package://rcm/meshes/Link3_2.STL" />
      </geometry>
      <material
        name="">
        <color
          rgba="0.79216 0.81961 0.93333 1" />
      </material>
    </visual>
    <collision>
      <origin
        xyz="0 0 0"
        rpy="0 0 0" />
      <geometry>
        <mesh
          filename="package://rcm/meshes/Link3_2.STL" />
      </geometry>
    </collision>
  </link>
  <joint
    name="Link3_2_joint"
    type="revolute">
    <origin
      xyz="0.0001 0.103 0.05"
      rpy="1.5708 0 0" />
    <parent
      link="Link2_1" />
    <child
      link="Link3_2" />
    <axis
      xyz="0 0 0" />
    <limit
      lower="-1.57"
      upper="1.57"
      effort="1000"
      velocity="0.2" />
    <mimic
      joint="Link3_1_joint"
      multiplier="1"
      offset="0" />
  </joint>
  <link
    name="Link2_2">
    <inertial>
      <origin
        xyz="2.7756E-17 0.0075 0.0048895"
        rpy="0 0 0" />
      <mass
        value="0.039322" />
      <inertia
        ixx="4.3641E-05"
        ixy="-2.021E-22"
        ixz="-1.6411E-20"
        iyy="4.6463E-05"
        iyz="-5.7105E-19"
        izz="4.29E-06" />
    </inertial>
    <visual>
      <origin
        xyz="0 0 0"
        rpy="0 0 0" />
      <geometry>
        <mesh
          filename="package://rcm/meshes/Link2_2.STL" />
      </geometry>
      <material
        name="">
        <color
          rgba="0.79216 0.81961 0.93333 1" />
      </material>
    </visual>
    <collision>
      <origin
        xyz="0 0 0"
        rpy="0 0 0" />
      <geometry>
        <mesh
          filename="package://rcm/meshes/Link2_2.STL" />
      </geometry>
    </collision>
  </link>
  <joint
    name="Link2_2_joint"
    type="revolute">
    <origin
      xyz="-0.0189 0.0926 0.053776"
      rpy="0 -0.33972 0" />
    <parent
      link="Link1" />
    <child
      link="Link2_2" />
    <axis
      xyz="0 0 0" />
    <limit
      lower="-1.57"
      upper="1.57"
      effort="1000"
      velocity="0.2" />
    <mimic
      joint="Link2_1_joint"
      multiplier="1"
      offset="0" />
  </joint>
</robot>